Workbook

Sheet ClientBrief
B2: CLIENT BRIEF - HYPOTHETICAL CASE
B3: Constructed for academic purposes. Not a real client. No personal advice is provided.
B6: HOUSEHOLD
B7: Client 1 | C7: Daniel Whitmore, age 38. Marketing manager, private sector. Gross salary $105,000 plus super.
B8: Client 2 | C8: Priya Whitmore, age 36. Registered nurse, NSW public health. Gross salary $88,000 plus super.
B9: Dependants | C9: One child, age 4. No plans for a second.
B10: Residence | C10: Own home in western Sydney, purchased 2021 for $980,000, current estimate $1,050,000.
B12: POSITION
B13: Superannuation | C13: Daniel $92,000 in a retail fund. Priya $68,000 in an industry fund. Gap reflects Priya's 18-month career break in 2021-22.
B14: Mortgage | C14: $720,000 outstanding, 25 years remaining, variable at 5.90%.
B15: Outside super | C15: $45,000 in the offset account, $25,000 in a broad-market ETF held since 2023.
B16: Surplus | C16: Approximately $34,000 per year of pre-tax income is uncommitted after living costs and the scheduled mortgage repayment.
B18: GOALS STATED BY THE CLIENT
B19: Goal 1 | C19: Retire at 67 with the ASFA comfortable couple standard, currently $78,566 per year.
B20: Goal 2 | C20: Clear the mortgage before retirement, ideally well before.
B21: Goal 3 | C21: Understand whether the surplus is better used on super, the mortgage, or investing outside super.
B23: RISK AND CONSTRAINTS
B24: Risk profile | C24: Balanced to growth. Daniel comfortable with volatility, Priya less so. Household agreed on a growth-tilted allocation with a three-month cash buffer.
B25: Liquidity | C25: Priya wants funds accessible before preservation age in case of a career change. This constrains a super-only strategy.
B26: Known issue | C26: Daniel's retail fund charges roughly 1.35% all-in versus around 0.65% for a comparable MySuper option.
B28: CONSTRUCTION OF THE PROFILE
B29: Income | C29: Set near AWOTE for full-time professionals. Source: ABS Average Weekly Earnings.
B30: Super balances | C30: Positioned near the median for the 35-39 age band. Source: ATO Taxation Statistics, super account balances by age.
B31: Fees | C31: Retail and MySuper fee levels drawn from APRA Quarterly Superannuation Performance statistics.
B32: Retirement target | C32: ASFA Retirement Standard, March quarter 2026: comfortable couple $78,566 per year, lump sum benchmark $730,000.
B33: Mortgage rate | C33: Consistent with RBA housing lending rates, standard variable, owner-occupier.
B36: THE ADVICE QUESTION | C36: Given $34,000 of pre-tax surplus per year, what allocation between concessional super contributions, extra mortgage repayments and investment outside super gives the household the best chance of meeting the ASFA comfortable standard at 67 without breaching their liquidity constraint?

Sheet Inputs
B2: INPUTS
B3: Blue = input you can change. Black = formula. Yellow = key assumption worth stress testing.
B5: CLIENT 1
B6: Name | C6: Daniel Whitmore
B7: Current age | C7: 38
B8: Gross salary ($ p.a.) | C8: 105000 | F8: ABS AWEO, full-time adult ordinary time earnings
B9: Super balance ($) | C9: 92000 | F9: ATO Taxation Statistics, median 35-39 band
B11: CLIENT 2
B12: Name | C12: Priya Whitmore
B13: Current age | C13: 36
B14: Gross salary ($ p.a.) | C14: 88000
B15: Super balance ($) | C15: 68000 | F15: Lower balance reflects an 18-month career break
B17: HOUSEHOLD
B18: Retirement age (both) | C18: 67
B19: Projection years | C19: =C18-C7 -> 29 | F19: Driven by Client 1's age
B20: Living expenses ($ p.a., today) | C20: 96000 | F20: Excludes mortgage repayments
B21: Pre-tax surplus available ($ p.a.) | C21: 34000 | F21: The amount the strategies compete for
B22: Blended marginal tax rate incl. Medicare | C22: 0.32 | F22: 30% bracket + 2% Medicare levy. Used to convert pre-tax surplus to after-tax.
B24: MORTGAGE
B25: Balance outstanding ($) | C25: 720000
B26: Interest rate (p.a.) | C26: 0.059 | F26: RBA housing lending rates, owner-occupier variable
B27: Term remaining (years) | C27: 25
B28: Scheduled annual repayment ($) | C28: =-PMT(C26,C27,C25) -> 55789.167 | F28: Annual PMT on the balance, rate and term above
B30: OUTSIDE SUPER
B31: Offset / cash ($) | C31: 45000
B32: ETF portfolio ($) | C32: 25000
B34: MARKET AND FEE ASSUMPTIONS
B35: Super gross return (p.a.) | C35: 0.07 | F35: Growth-tilted option, long-run nominal
B36: Outside-super gross return (p.a.) | C36: 0.065 | F36: Net of an assumed tax drag on distributions
B37: Return volatility (std dev, p.a.) | C37: 0.115 | F37: Used only by the Monte Carlo sheet
B38: Inflation (p.a.) | C38: 0.025 | F38: RBA target midpoint
B39: Wage growth (p.a.) | C39: 0.03
B40: Current fund fee (p.a.) | C40: 0.0135 | F40: Retail fund, all-in. APRA Quarterly Super Performance
B41: Alternative MySuper fee (p.a.) | C41: 0.0065 | F41: Comparable MySuper balanced option
B42: FEE APPLIED IN MODEL | C42: 0.0135 | F42: Switch between the two above to run the fee comparison
B44: SCENARIO SWITCH
B45: Active scenario (1-4) | C45: 1 | F45: Drives the Engine sheet. Scenarios sheet runs all four at once.
B47: STRATEGY TABLE
B48: # | C48: Strategy | D48: Salary sacrifice (pre-tax $) | E48: Extra mortgage (after-tax $) | F48: Outside investment (after-tax $)
B49: 1 | C49: Base case - surplus invested outside super | D49: 0 | E49: 0 | F49: =$C$21*(1-$C$22) -> 23120
...

Sheet Rules
B2: RULES AND THRESHOLDS - FY2026-27
B3: Every rate the model uses lives here. Formulas reference these cells, never a typed number. Update this sheet each 1 July.
B5: RESIDENT INCOME TAX SCALE
B6: Lower threshold ($) | C6: Upper threshold ($) | D6: Marginal rate | E6: Incremental rate
B7: 0 | C7: 18200 | D7: 0 | E7: 0 | F7: Source: ATO, Tax rates - Australian resident, 2026-27. The 15% rate took effect 1 July 2026.
B8: 18200 | C8: 45000 | D8: 0.15 | E8: 0.15 | F8: Incremental rate = this bracket's rate less the previous bracket's. Used by the SUMPRODUCT tax formula.
B9: 45000 | C9: 135000 | D9: 0.3 | E9: 0.15
B10: 135000 | C10: 190000 | D10: 0.37 | E10: 0.07
B11: 190000 | C11: and above | D11: 0.45 | E11: 0.08
B13: SUPERANNUATION AND OTHER PARAMETERS
B14: Medicare levy | C14: 0.02 | F14: ATO. Low-income shade-in ignored; immaterial at these incomes.
B15: Superannuation guarantee rate | C15: 0.12 | F15: ATO. 12% from 1 July 2025, unchanged for 2026-27.
B16: Maximum contribution base ($ p.a.) | C16: 270830 | F16: ATO 2026-27. Applied annually here; in practice it is a quarterly test.
B17: Concessional contributions cap ($) | C17: 32500 | F17: ATO 2026-27, indexed up from $30,000.
B18: Contributions tax | C18: 0.15 | F18: Tax on concessional contributions inside the fund.
B19: Division 293 income threshold ($) | C19: 250000 | F19: ATO. Neither client reaches this, but the logic is built in.
B20: Division 293 additional tax | C20: 0.15 | F20: Extra 15% on concessional contributions above the threshold.
B21: Non-concessional cap ($) | C21: 130000 | F21: ATO 2026-27, up from $120,000. Not used in the base strategies.
B22: Preservation age | C22: 60 | F22: Age 60 for anyone born after 30 June 1964.
B23: Transfer balance cap ($) | C23: 2100000 | F23: ATO, from 1 July 2026.
B24: CGT discount (assets held > 12 months) | C24: 0.5 | F24: Applies to the outside-super portfolio.
B25: ASFA comfortable - couple, annual ($) | C25: 78566 | F25: ASFA Retirement Standard, March quarter 2026. Homeowners.
... B29: Safe withdrawal rate | C29: 0.04 | F29: Used to convert a capital balance into a sustainable retirement income.
B30: SIMPLIFICATIONS - state these in the write-up
B31: - Age Pension entitlement is not modelled. Including it would raise the projected retirement income and is a natural extension.
B32: - Medicare levy is applied flat at 2%; the low-income shade-in and the surcharge are ignored.
B33: - Tax offsets (LITO, SAPTO) are ignored.
B34: - Outside-super returns are modelled net of an assumed tax drag rather than year-by-year CGT and franking.
B35: - Both clients are assumed to work continuously to age 67 with no further career breaks.
B36: - The maximum contribution base is applied annually rather than quarterly.

Sheet Engine
A2: ENGINE | K2: Active strategy: | M2: =INDEX(Inputs!$C$49:$C$52,Inputs!$C$45) -> Base case - surplus invested outside super
A3: Change the active scenario on the Inputs sheet. The Scenarios sheet runs all four side by side. | K3: All checks OK: | M3: =IF(COUNTIF(AQ7:AQ36,"CHECK")=0,"YES","REVIEW") -> YES
A6: Year | B6: Financial year | C6: Age - D | D6: Age - P | E6: Salary - D ($) | F6: Salary - P ($) | G6: Salary sacrifice - D ($) | H6: Salary sacrifice - P ($) | I6: SG - D ($) | J6: SG - P ($) | K6: Concessional - D ($) | L6: Concessional - P ($) | M6: Concessional cap ($) | N6: Excess - D ($) | O6: Excess - P ($) | P6: Taxable income - D ($) | Q6: Taxable income - P ($) | R6: Income tax - D ($) | S6: Income tax - P ($) | T6: Net household income ($) | U6: Living expenses ($) | V6: Mortgage open ($) | W6: Interest ($) | X6: Scheduled repayment ($) | Y6: Extra repayment ($) | Z6: Mortgage close ($) | AA6: Outside open ($) | AB6: Outside contribution ($) | AC6: Outside return ($) | AD6: Outside close ($) | AE6: Super open - D ($) | AF6: Net contributions - D ($) | AG6: Return - D ($) | AH6: Fees - D ($) | AI6: Super close - D ($) | AJ6: Super open - P ($) | AK6: Net contributions - P ($) | AL6: Return - P ($) | AM6: Fees - P ($) | AN6: Super close - P ($) | AO6: Total super ($) | AP6: Net wealth ($) | AQ6: Check
A7: 1 | B7: FY27 | C7: =Inputs!$C$7+A7-1 -> 38 | D7: =Inputs!$C$13+A7-1 -> 36 | E7: =Inputs!$C$8*(1+Inputs!$C$39)^(A7-1) -> 105000 | F7: =Inputs!$C$14*(1+Inputs!$C$39)^(A7-1) -> 88000 | G7: =INDEX(Inputs!$D$49:$D$52,Inputs!$C$45)*(1+Inputs!$C$39)^(A7-1)*E7/(E7+F7) -> 0 | H7: =INDEX(Inputs!$D$49:$D$52,Inputs!$C$45)*(1+Inputs!$C$39)^(A7-1)*F7/(E7+F7) -> 0 | I7: =MIN(E7,Rules!$C$16*(1+Inputs!$C$39)^(A7-1))*Rules!$C$15 -> 12600 | J7: =MIN(F7,Rules!$C$16*(1+Inputs!$C$39)^(A7-1))*Rules!$C$15 -> 10560 | K7: =G7+I7 -> 12600 | L7: =H7+J7 -> 10560 | M7: =Rules!$C$17*(1+Inputs!$C$39)^(A7-1) -> 32500 | N7: =MAX(0,K7-M7) -> 0 | O7: =MAX(0,L7-M7) -> 0 | P7: =E7-G7 -> 105000 | Q7: =F7-H7 -> 88000 | R7: =SUMPRODUCT(--(P7>Rules!$B$7:$B$11),(P7-Rules!$B$7:$B$11),Rules!$E$7:$E$11)+P7*Rules!$C$14 -> 24120 | S7: =SUMPRODUCT(--(Q7>Rules!$B$7:$B$11),(Q7-Rules!$B$7:$B$11),Rules!$E$7:$E$11)+Q7*Rules!$C$14 -> 18680 | T7: =(P7-R7)+(Q7-S7) -> 150200 | U7: =Inputs!$C$20*(1+Inputs!$C$38)^(A7-1) -> 96000 | V7: =Inputs!$C$25 -> 720000 | W7: =V7*Inputs!$C$26 -> 42480 | X7: =IF(V7<=0,0,MIN(Inputs!$C$28,V7+W7)) -> 55789.167 | Y7: =IF(V7<=0,0,MIN(INDEX(Inputs!$E$49:$E$52,Inputs!$C$45),MAX(0,V7+W7-X7))) -> 0 | Z7: =MAX(0,V7+W7-X7-Y7) -> 706690.83 | AA7: =Inputs!$C$31+Inputs!$C$32 -> 70000 | AB7: =INDEX(Inputs!$F$49:$F$52,Inputs!$C$45)+IF(V7<=0,Inputs!$C$28+INDEX(Inputs!$E$49:$E$52,Inputs!$C$45),0) -> 23120 | AC7: =(AA7+AB7/2)*Inputs!$C$36 -> 5301.4 | AD7: =AA7+AB7+AC7 -> 98421.4 | AE7: =Inputs!$C$9 -> 92000 | AF7: =K7*(1-Rules!$C$18)-MAX(0,MIN(K7,P7+K7-Rules!$C$19))*Rules!$C$20 -> 10710 | AG7: =(AE7+AF7/2)*Inputs!$C$35 -> 6814.85 | AH7: =(AE7+AF7/2)*Inputs!$C$42 -> 1314.2925 | AI7: =AE7+AF7+AG7-AH7 -> 108210.56 | AJ7: =Inputs!$C$15 -> 68000 | AK7: =L7*(1-Rules!$C$18)-MAX(0,MIN(L7,Q7+L7-Rules!$C$19))*Rules!$C$20 -> 8976 | AL7: =(AJ7+AK7/2)*Inputs!$C$35 -> 5074.16 | AM7: =(AJ7+AK7/2)*Inputs!$C$42 -> 978.588 | AN7: =AJ7+AK7+AL7-AM7 -> 81071.572 | AO7: =AI7+AN7 -> 189282.13 | AP7: =AO7+AD7-Z7 -> -418987.3 | AQ7: =IF(AND(N7=0,O7=0,Z7>=0,AI7>=0,AN7>=0),"OK","CHECK") -> OK
A8: 2 | B8: FY28 | C8: =Inputs!$C$7+A8-1 -> 39 | D8: =Inputs!$C$13+A8-1 -> 37 | E8: =Inputs!$C$8*(1+Inputs!$C$39)^(A8-1) -> 108150 | F8: =Inputs!$C$14*(1+Inputs!$C$39)^(A8-1) -> 90640 | G8: =INDEX(Inputs!$D$49:$D$52,Inputs!$C$45)*(1+Inputs!$C$39)^(A8-1)*E8/(E8+F8) -> 0 | H8: =INDEX(Inputs!$D$49:$D$52,Inputs!$C$45)*(1+Inputs!$C$39)^(A8-1)*F8/(E8+F8) -> 0 | I8: =MIN(E8,Rules!$C$16*(1+Inputs!$C$39)^(A8-1))*Rules!$C$15 -> 12978 | J8: =MIN(F8,Rules!$C$16*(1+Inputs!$C$39)^(A8-1))*Rules!$C$15 -> 10876.8 | K8: =G8+I8 -> 12978 | L8: =H8+J8 -> 10876.8 | M8: =Rules!$C$17*(1+Inputs!$C$39)^(A8-1) -> 33475 | N8: =MAX(0,K8-M8) -> 0 | O8: =MAX(0,L8-M8) -> 0 | P8: =E8-G8 -> 108150 | Q8: =F8-H8 -> 90640 | R8: =SUMPRODUCT(--(P8>Rules!$B$7:$B$11),(P8-Rules!$B$7:$B$11),Rules!$E$7:$E$11)+P8*Rules!$C$14 -> 25128 | S8: =SUMPRODUCT(--(Q8>Rules!$B$7:$B$11),(Q8-Rules!$B$7:$B$11),Rules!$E$7:$E$11)+Q8*Rules!$C$14 -> 19524.8 | T8: =(P8-R8)+(Q8-S8) -> 154137.2 | U8: =Inputs!$C$20*(1+Inputs!$C$38)^(A8-1) -> 98400 | V8: =Z7 -> 706690.83 | W8: =V8*Inputs!$C$26 -> 41694.759 | X8: =IF(V8<=0,0,MIN(Inputs!$C$28,V8+W8)) -> 55789.167 | Y8: =IF(V8<=0,0,MIN(INDEX(Inputs!$E$49:$E$52,Inputs!$C$45),MAX(0,V8+W8-X8))) -> 0 | Z8: =MAX(0,V8+W8-X8-Y8) -> 692596.43 | AA8: =AD7 -> 98421.4 | AB8: =INDEX(Inputs!$F$49:$F$52,Inputs!$C$45)+IF(V8<=0,Inputs!$C$28+INDEX(Inputs!$E$49:$E$52,Inputs!$C$45),0) -> 23120 | AC8: =(AA8+AB8/2)*Inputs!$C$36 -> 7148.791 | AD8: =AA8+AB8+AC8 -> 128690.19 | AE8: =AI7 -> 108210.56 | AF8: =K8*(1-Rules!$C$18)-MAX(0,MIN(K8,P8+K8-Rules!$C$19))*Rules!$C$20 -> 11031.3 | AG8: =(AE8+AF8/2)*Inputs!$C$35 -> 7960.8345 | AH8: =(AE8+AF8/2)*Inputs!$C$42 -> 1535.3038 | AI8: =AE8+AF8+AG8-AH8 -> 125667.39 | AJ8: =AN7 -> 81071.572 | AK8: =L8*(1-Rules!$C$18)-MAX(0,MIN(L8,Q8+L8-Rules!$C$19))*Rules!$C$20 -> 9245.28 | AL8: =(AJ8+AK8/2)*Inputs!$C$35 -> 5998.5948 | AM8: =(AJ8+AK8/2)*Inputs!$C$42 -> 1156.8719 | AN8: =AJ8+AK8+AL8-AM8 -> 95158.575 | AO8: =AI8+AN8 -> 220825.96 | AP8: =AO8+AD8-Z8 -> -343080.27 | AQ8: =IF(AND(N8=0,O8=0,Z8>=0,AI8>=0,AN8>=0),"OK","CHECK") -> OK
A9: 3 | B9: FY29 | C9: =Inputs!$C$7+A9-1 -> 40 | D9: =Inputs!$C$13+A9-1 -> 38 | E9: =Inputs!$C$8*(1+Inputs!$C$39)^(A9-1) -> 111394.5 | F9: =Inputs!$C$14*(1+Inputs!$C$39)^(A9-1) -> 93359.2 | G9: =INDEX(Inputs!$D$49:$D$52,Inputs!$C$45)*(1+Inputs!$C$39)^(A9-1)*E9/(E9+F9) -> 0 | H9: =INDEX(Inputs!$D$49:$D$52,Inputs!$C$45)*(1+Inputs!$C$39)^(A9-1)*F9/(E9+F9) -> 0 | I9: =MIN(E9,Rules!$C$16*(1+Inputs!$C$39)^(A9-1))*Rules!$C$15 -> 13367.34 | J9: =MIN(F9,Rules!$C$16*(1+Inputs!$C$39)^(A9-1))*Rules!$C$15 -> 11203.104 | K9: =G9+I9 -> 13367.34 | L9: =H9+J9 -> 11203.104 | M9: =Rules!$C$17*(1+Inputs!$C$39)^(A9-1) -> 34479.25 | N9: =MAX(0,K9-M9) -> 0 | O9: =MAX(0,L9-M9) -> 0 | P9: =E9-G9 -> 111394.5 | Q9: =F9-H9 -> 93359.2 | R9: =SUMPRODUCT(--(P9>Rules!$B$7:$B$11),(P9-Rules!$B$7:$B$11),Rules!$E$7:$E$11)+P9*Rules!$C$14 -> 26166.24 | S9: =SUMPRODUCT(--(Q9>Rules!$B$7:$B$11),(Q9-Rules!$B$7:$B$11),Rules!$E$7:$E$11)+Q9*Rules!$C$14 -> 20394.944 | T9: =(P9-R9)+(Q9-S9) -> 158192.52 | U9: =Inputs!$C$20*(1+Inputs!$C$38)^(A9-1) -> 100860 | V9: =Z8 -> 692596.43 | W9: =V9*Inputs!$C$26 -> 40863.189 | X9: =IF(V9<=0,0,MIN(Inputs!$C$28,V9+W9)) -> 55789.167 | Y9: =IF(V9<=0,0,MIN(INDEX(Inputs!$E$49:$E$52,Inputs!$C$45),MAX(0,V9+W9-X9))) -> 0 | Z9: =MAX(0,V9+W9-X9-Y9) -> 677670.45 | AA9: =AD8 -> 128690.19 | AB9: =INDEX(Inputs!$F$49:$F$52,Inputs!$C$45)+IF(V9<=0,Inputs!$C$28+INDEX(Inputs!$E$49:$E$52,Inputs!$C$45),0) -> 23120 | AC9: =(AA9+AB9/2)*Inputs!$C$36 -> 9116.2624 | AD9: =AA9+AB9+AC9 -> 160926.45 | AE9: =AI8 -> 125667.39 | AF9: =K9*(1-Rules!$C$18)-MAX(0,MIN(K9,P9+K9-Rules!$C$19))*Rules!$C$20 -> 11362.239 | AG9: =(AE9+AF9/2)*Inputs!$C$35 -> 9194.3955 | AH9: =(AE9+AF9/2)*Inputs!$C$42 -> 1773.2049 | AI9: =AE9+AF9+AG9-AH9 -> 144450.82 | AJ9: =AN8 -> 95158.575 | AK9: =L9*(1-Rules!$C$18)-MAX(0,MIN(L9,Q9+L9-Rules!$C$19))*Rules!$C$20 -> 9522.6384 | AL9: =(AJ9+AK9/2)*Inputs!$C$35 -> 6994.3926 | AM9: =(AJ9+AK9/2)*Inputs!$C$42 -> 1348.9186 | AN9: =AJ9+AK9+AL9-AM9 -> 110326.69 | AO9: =AI9+AN9 -> 254777.51 | AP9: =AO9+AD9-Z9 -> -261966.49 | AQ9: =IF(AND(N9=0,O9=0,Z9>=0,AI9>=0,AN9>=0),"OK","CHECK") -> OK
A10: 4 | B10: FY30 | C10: =Inputs!$C$7+A10-1 -> 41 | D10: =Inputs!$C$13+A10-1 -> 39 | E10: =Inputs!$C$8*(1+Inputs!$C$39)^(A10-1) -> 114736.34 | F10: =Inputs!$C$14*(1+Inputs!$C$39)^(A10-1) -> 96159.976 | G10: =INDEX(Inputs!$D$49:$D$52,Inputs!$C$45)*(1+Inputs!$C$39)^(A10-1)*E10/(E10+F10) -> 0 | H10: =INDEX(Inputs!$D$49:$D$52,Inputs!$C$45)*(1+Inputs!$C$39)^(A10-1)*F10/(E10+F10) -> 0 | I10: =MIN(E10,Rules!$C$16*(1+Inputs!$C$39)^(A10-1))*Rules!$C$15 -> 13768.36 | J10: =MIN(F10,Rules!$C$16*(1+Inputs!$C$39)^(A10-1))*Rules!$C$15 -> 11539.197 | K10: =G10+I10 -> 13768.36 | L10: =H10+J10 -> 11539.197 | M10: =Rules!$C$17*(1+Inputs!$C$39)^(A10-1) -> 35513.628 | N10: =MAX(0,K10-M10) -> 0 | O10: =MAX(0,L10-M10) -> 0 | P10: =E10-G10 -> 114736.34 | Q10: =F10-H10 -> 96159.976 | R10: =SUMPRODUCT(--(P10>Rules!$B$7:$B$11),(P10-Rules!$B$7:$B$11),Rules!$E$7:$E$11)+P10*Rules!$C$14 -> 27235.627 | S10: =SUMPRODUCT(--(Q10>Rules!$B$7:$B$11),(Q10-Rules!$B$7:$B$11),Rules!$E$7:$E$11)+Q10*Rules!$C$14 -> 21291.192 | T10: =(P10-R10)+(Q10-S10) -> 162369.49 | U10: =Inputs!$C$20*(1+Inputs!$C$38)^(A10-1) -> 103381.5 | V10: =Z9 -> 677670.45 | W10: =V10*Inputs!$C$26 -> 39982.556 | X10: =IF(V10<=0,0,MIN(Inputs!$C$28,V10+W10)) -> 55789.167 | Y10: =IF(V10<=0,0,MIN(INDEX(Inputs!$E$49:$E$52,Inputs!$C$45),MAX(0,V10+W10-X10))) -> 0 | Z10: =MAX(0,V10+W10-X10-Y10) -> 661863.84 | AA10: =AD9 -> 160926.45 | AB10: =INDEX(Inputs!$F$49:$F$52,Inputs!$C$45)+IF(V10<=0,Inputs!$C$28+INDEX(Inputs!$E$49:$E$52,Inputs!$C$45),0) -> 23120 | AC10: =(AA10+AB10/2)*Inputs!$C$36 -> 11211.619 | AD10: =AA10+AB10+AC10 -> 195258.07 | AE10: =AI9 -> 144450.82 | AF10: =K10*(1-Rules!$C$18)-MAX(0,MIN(K10,P10+K10-Rules!$C$19))*Rules!$C$20 -> 11703.106 | AG10: =(AE10+AF10/2)*Inputs!$C$35 -> 10521.166 | AH10: =(AE10+AF10/2)*Inputs!$C$42 -> 2029.082 | AI10: =AE10+AF10+AG10-AH10 -> 164646.01 | AJ10: =AN9 -> 110326.69 | AK10: =L10*(1-Rules!$C$18)-MAX(0,MIN(L10,Q10+L10-Rules!$C$19))*Rules!$C$20 -> 9808.3176 | AL10: =(AJ10+AK10/2)*Inputs!$C$35 -> 8066.1592 | AM10: =(AJ10+AK10/2)*Inputs!$C$42 -> 1555.6164 | AN10: =AJ10+AK10+AL10-AM10 -> 126645.55 | AO10: =AI10+AN10 -> 291291.56 | AP10: =AO10+AD10-Z10 -> -175314.21 | AQ10: =IF(AND(N10=0,O10=0,Z10>=0,AI10>=0,AN10>=0),"OK","CHECK") -> OK
A11: 5 | B11: FY31 | C11: =Inputs!$C$7+A11-1 -> 42 | D11: =Inputs!$C$13+A11-1 -> 40 | E11: =Inputs!$C$8*(1+Inputs!$C$39)^(A11-1) -> 118178.43 | F11: =Inputs!$C$14*(1+Inputs!$C$39)^(A11-1) -> 99044.775 | G11: =INDEX(Inputs!$D$49:$D$52,Inputs!$C$45)*(1+Inputs!$C$39)^(A11-1)*E11/(E11+F11) -> 0 | H11: =INDEX(Inputs!$D$49:$D$52,Inputs!$C$45)*(1+Inputs!$C$39)^(A11-1)*F11/(E11+F11) -> 0 | I11: =MIN(E11,Rules!$C$16*(1+Inputs!$C$39)^(A11-1))*Rules!$C$15 -> 14181.411 | J11: =MIN(F11,Rules!$C$16*(1+Inputs!$C$39)^(A11-1))*Rules!$C$15 -> 11885.373 | K11: =G11+I11 -> 14181.411 | L11: =H11+J11 -> 11885.373 | M11: =Rules!$C$17*(1+Inputs!$C$39)^(A11-1) -> 36579.036 | N11: =MAX(0,K11-M11) -> 0 | O11: =MAX(0,L11-M11) -> 0 | P11: =E11-G11 -> 118178.43 | Q11: =F11-H11 -> 99044.775 | R11: =SUMPRODUCT(--(P11>Rules!$B$7:$B$11),(P11-Rules!$B$7:$B$11),Rules!$E$7:$E$11)+P11*Rules!$C$14 -> 28337.096 | S11: =SUMPRODUCT(--(Q11>Rules!$B$7:$B$11),(Q11-Rules!$B$7:$B$11),Rules!$E$7:$E$11)+Q11*Rules!$C$14 -> 22214.328 | T11: =(P11-R11)+(Q11-S11) -> 166671.78 | U11: =Inputs!$C$20*(1+Inputs!$C$38)^(A11-1) -> 105966.04 | V11: =Z10 -> 661863.84 | W11: =V11*Inputs!$C$26 -> 39049.966 | X11: =IF(V11<=0,0,MIN(Inputs!$C$28,V11+W11)) -> 55789.167 | Y11: =IF(V11<=0,0,MIN(INDEX(Inputs!$E$49:$E$52,Inputs!$C$45),MAX(0,V11+W11-X11))) -> 0 | Z11: =MAX(0,V11+W11-X11-Y11) -> 645124.64 | AA11: =AD10 -> 195258.07 | AB11: =INDEX(Inputs!$F$49:$F$52,Inputs!$C$45)+IF(V11<=0,Inputs!$C$28+INDEX(Inputs!$E$49:$E$52,Inputs!$C$45),0) -> 23120 | AC11: =(AA11+AB11/2)*Inputs!$C$36 -> 13443.175 | AD11: =AA11+AB11+AC11 -> 231821.25 | AE11: =AI10 -> 164646.01 | AF11: =K11*(1-Rules!$C$18)-MAX(0,MIN(K11,P11+K11-Rules!$C$19))*Rules!$C$20 -> 12054.199 | AG11: =(AE11+AF11/2)*Inputs!$C$35 -> 11947.118 | AH11: =(AE11+AF11/2)*Inputs!$C$42 -> 2304.087 | AI11: =AE11+AF11+AG11-AH11 -> 186343.24 | AJ11: =AN10 -> 126645.55 | AK11: =L11*(1-Rules!$C$18)-MAX(0,MIN(L11,Q11+L11-Rules!$C$19))*Rules!$C$20 -> 10102.567 | AL11: =(AJ11+AK11/2)*Inputs!$C$35 -> 9218.7782 | AM11: =(AJ11+AK11/2)*Inputs!$C$42 -> 1777.9072 | AN11: =AJ11+AK11+AL11-AM11 -> 144188.99 | AO11: =AI11+AN11 -> 330532.22 | AP11: =AO11+AD11-Z11 -> -82771.165 | AQ11: =IF(AND(N11=0,O11=0,Z11>=0,AI11>=0,AN11>=0),"OK","CHECK") -> OK
A12: 6 | B12: FY32 | C12: =Inputs!$C$7+A12-1 -> 43 | D12: =Inputs!$C$13+A12-1 -> 41 | E12: =Inputs!$C$8*(1+Inputs!$C$39)^(A12-1) -> 121723.78 | F12: =Inputs!$C$14*(1+Inputs!$C$39)^(A12-1) -> 102016.12 | G12: =INDEX(Inputs!$D$49:$D$52,Inputs!$C$45)*(1+Inputs!$C$39)^(A12-1)*E12/(E12+F12) -> 0 | H12: =INDEX(Inputs!$D$49:$D$52,Inputs!$C$45)*(1+Inputs!$C$39)^(A12-1)*F12/(E12+F12) -> 0 | I12: =MIN(E12,Rules!$C$16*(1+Inputs!$C$39)^(A12-1))*Rules!$C$15 -> 14606.853 | J12: =MIN(F12,Rules!$C$16*(1+Inputs!$C$39)^(A12-1))*Rules!$C$15 -> 12241.934 | K12: =G12+I12 -> 14606.853 | L12: =H12+J12 -> 12241.934 | M12: =Rules!$C$17*(1+Inputs!$C$39)^(A12-1) -> 37676.407 | N12: =MAX(0,K12-M12) -> 0 | O12: =MAX(0,L12-M12) -> 0 | P12: =E12-G12 -> 121723.78 | Q12: =F12-H12 -> 102016.12 | R12: =SUMPRODUCT(--(P12>Rules!$B$7:$B$11),(P12-Rules!$B$7:$B$11),Rules!$E$7:$E$11)+P12*Rules!$C$14 -> 29471.609 | S12: =SUMPRODUCT(--(Q12>Rules!$B$7:$B$11),(Q12-Rules!$B$7:$B$11),Rules!$E$7:$E$11)+Q12*Rules!$C$14 -> 23165.158 | T12: =(P12-R12)+(Q12-S12) -> 171103.13 | U12: =Inputs!$C$20*(1+Inputs!$C$38)^(A12-1) -> 108615.19 | V12: =Z11 -> 645124.64 | W12: =V12*Inputs!$C$26 -> 38062.354 | X12: =IF(V12<=0,0,MIN(Inputs!$C$28,V12+W12)) -> 55789.167 | Y12: =IF(V12<=0,0,MIN(INDEX(Inputs!$E$49:$E$52,Inputs!$C$45),MAX(0,V12+W12-X12))) -> 0 | Z12: =MAX(0,V12+W12-X12-Y12) -> 627397.82 | AA12: =AD11 -> 231821.25 | AB12: =INDEX(Inputs!$F$49:$F$52,Inputs!$C$45)+IF(V12<=0,Inputs!$C$28+INDEX(Inputs!$E$49:$E$52,Inputs!$C$45),0) -> 23120 | AC12: =(AA12+AB12/2)*Inputs!$C$36 -> 15819.781 | AD12: =AA12+AB12+AC12 -> 270761.03 | AE12: =AI11 -> 186343.24 | AF12: =K12*(1-Rules!$C$18)-MAX(0,MIN(K12,P12+K12-Rules!$C$19))*Rules!$C$20 -> 12415.825 | AG12: =(AE12+AF12/2)*Inputs!$C$35 -> 13478.581 | AH12: =(AE12+AF12/2)*Inputs!$C$42 -> 2599.4405 | AI12: =AE12+AF12+AG12-AH12 -> 209638.2 | AJ12: =AN11 -> 144188.99 | AK12: =L12*(1-Rules!$C$18)-MAX(0,MIN(L12,Q12+L12-Rules!$C$19))*Rules!$C$20 -> 10405.644 | AL12: =(AJ12+AK12/2)*Inputs!$C$35 -> 10457.427 | AM12: =(AJ12+AK12/2)*Inputs!$C$42 -> 2016.7894 | AN12: =AJ12+AK12+AL12-AM12 -> 163035.27 | AO12: =AI12+AN12 -> 372673.47 | AP12: =AO12+AD12-Z12 -> 16036.677 | AQ12: =IF(AND(N12=0,O12=0,Z12>=0,AI12>=0,AN12>=0),"OK","CHECK") -> OK
A13: 7 | B13: FY33 | C13: =Inputs!$C$7+A13-1 -> 44 | D13: =Inputs!$C$13+A13-1 -> 42 | E13: =Inputs!$C$8*(1+Inputs!$C$39)^(A13-1) -> 125375.49 | F13: =Inputs!$C$14*(1+Inputs!$C$39)^(A13-1) -> 105076.6 | G13: =INDEX(Inputs!$D$49:$D$52,Inputs!$C$45)*(1+Inputs!$C$39)^(A13-1)*E13/(E13+F13) -> 0 | H13: =INDEX(Inputs!$D$49:$D$52,Inputs!$C$45)*(1+Inputs!$C$39)^(A13-1)*F13/(E13+F13) -> 0 | I13: =MIN(E13,Rules!$C$16*(1+Inputs!$C$39)^(A13-1))*Rules!$C$15 -> 15045.059 | J13: =MIN(F13,Rules!$C$16*(1+Inputs!$C$39)^(A13-1))*Rules!$C$15 -> 12609.192 | K13: =G13+I13 -> 15045.059 | L13: =H13+J13 -> 12609.192 | M13: =Rules!$C$17*(1+Inputs!$C$39)^(A13-1) -> 38806.7 | N13: =MAX(0,K13-M13) -> 0 | O13: =MAX(0,L13-M13) -> 0 | P13: =E13-G13 -> 125375.49 | Q13: =F13-H13 -> 105076.6 | R13: =SUMPRODUCT(--(P13>Rules!$B$7:$B$11),(P13-Rules!$B$7:$B$11),Rules!$E$7:$E$11)+P13*Rules!$C$14 -> 30640.157 | S13: =SUMPRODUCT(--(Q13>Rules!$B$7:$B$11),(Q13-Rules!$B$7:$B$11),Rules!$E$7:$E$11)+Q13*Rules!$C$14 -> 24144.513 | T13: =(P13-R13)+(Q13-S13) -> 175667.42 | U13: =Inputs!$C$20*(1+Inputs!$C$38)^(A13-1) -> 111330.57 | V13: =Z12 -> 627397.82 | W13: =V13*Inputs!$C$26 -> 37016.472 | X13: =IF(V13<=0,0,MIN(Inputs!$C$28,V13+W13)) -> 55789.167 | Y13: =IF(V13<=0,0,MIN(INDEX(Inputs!$E$49:$E$52,Inputs!$C$45),MAX(0,V13+W13-X13))) -> 0 | Z13: =MAX(0,V13+W13-X13-Y13) -> 608625.13 | AA13: =AD12 -> 270761.03 | AB13: =INDEX(Inputs!$F$49:$F$52,Inputs!$C$45)+IF(V13<=0,Inputs!$C$28+INDEX(Inputs!$E$49:$E$52,Inputs!$C$45),0) -> 23120 | AC13: =(AA13+AB13/2)*Inputs!$C$36 -> 18350.867 | AD13: =AA13+AB13+AC13 -> 312231.9 | AE13: =AI12 -> 209638.2 | AF13: =K13*(1-Rules!$C$18)-MAX(0,MIN(K13,P13+K13-Rules!$C$19))*Rules!$C$20 -> 12788.3 | AG13: =(AE13+AF13/2)*Inputs!$C$35 -> 15122.265 | AH13: =(AE13+AF13/2)*Inputs!$C$42 -> 2916.4368 | AI13: =AE13+AF13+AG13-AH13 -> 234632.33 | AJ13: =AN12 -> 163035.27 | AK13: =L13*(1-Rules!$C$18)-MAX(0,MIN(L13,Q13+L13-Rules!$C$19))*Rules!$C$20 -> 10717.813 | AL13: =(AJ13+AK13/2)*Inputs!$C$35 -> 11787.592 | AM13: =(AJ13+AK13/2)*Inputs!$C$42 -> 2273.3213 | AN13: =AJ13+AK13+AL13-AM13 -> 183267.35 | AO13: =AI13+AN13 -> 417899.68 | AP13: =AO13+AD13-Z13 -> 121506.45 | AQ13: =IF(AND(N13=0,O13=0,Z13>=0,AI13>=0,AN13>=0),"OK","CHECK") -> OK
A14: 8 | B14: FY34 | C14: =Inputs!$C$7+A14-1 -> 45 | D14: =Inputs!$C$13+A14-1 -> 43 | E14: =Inputs!$C$8*(1+Inputs!$C$39)^(A14-1) -> 129136.76 | F14: =Inputs!$C$14*(1+Inputs!$C$39)^(A14-1) -> 108228.9 | G14: =INDEX(Inputs!$D$49:$D$52,Inputs!$C$45)*(1+Inputs!$C$39)^(A14-1)*E14/(E14+F14) -> 0 | H14: =INDEX(Inputs!$D$49:$D$52,Inputs!$C$45)*(1+Inputs!$C$39)^(A14-1)*F14/(E14+F14) -> 0 | I14: =MIN(E14,Rules!$C$16*(1+Inputs!$C$39)^(A14-1))*Rules!$C$15 -> 15496.411 | J14: =MIN(F14,Rules!$C$16*(1+Inputs!$C$39)^(A14-1))*Rules!$C$15 -> 12987.468 | K14: =G14+I14 -> 15496.411 | L14: =H14+J14 -> 12987.468 | M14: =Rules!$C$17*(1+Inputs!$C$39)^(A14-1) -> 39970.901 | N14: =MAX(0,K14-M14) -> 0 | O14: =MAX(0,L14-M14) -> 0 | P14: =E14-G14 -> 129136.76 | Q14: =F14-H14 -> 108228.9 | R14: =SUMPRODUCT(--(P14>Rules!$B$7:$B$11),(P14-Rules!$B$7:$B$11),Rules!$E$7:$E$11)+P14*Rules!$C$14 -> 31843.762 | S14: =SUMPRODUCT(--(Q14>Rules!$B$7:$B$11),(Q14-Rules!$B$7:$B$11),Rules!$E$7:$E$11)+Q14*Rules!$C$14 -> 25153.248 | T14: =(P14-R14)+(Q14-S14) -> 180368.65 | U14: =Inputs!$C$20*(1+Inputs!$C$38)^(A14-1) -> 114113.83 | V14: =Z13 -> 608625.13 | W14: =V14*Inputs!$C$26 -> 35908.883 | X14: =IF(V14<=0,0,MIN(Inputs!$C$28,V14+W14)) -> 55789.167 | Y14: =IF(V14<=0,0,MIN(INDEX(Inputs!$E$49:$E$52,Inputs!$C$45),MAX(0,V14+W14-X14))) -> 0 | Z14: =MAX(0,V14+W14-X14-Y14) -> 588744.84 | AA14: =AD13 -> 312231.9 | AB14: =INDEX(Inputs!$F$49:$F$52,Inputs!$C$45)+IF(V14<=0,Inputs!$C$28+INDEX(Inputs!$E$49:$E$52,Inputs!$C$45),0) -> 23120 | AC14: =(AA14+AB14/2)*Inputs!$C$36 -> 21046.473 | AD14: =AA14+AB14+AC14 -> 356398.37 | AE14: =AI13 -> 234632.33 | AF14: =K14*(1-Rules!$C$18)-MAX(0,MIN(K14,P14+K14-Rules!$C$19))*Rules!$C$20 -> 13171.949 | AG14: =(AE14+AF14/2)*Inputs!$C$35 -> 16885.281 | AH14: =(AE14+AF14/2)*Inputs!$C$42 -> 3256.4471 | AI14: =AE14+AF14+AG14-AH14 -> 261433.11 | AJ14: =AN13 -> 183267.35 | AK14: =L14*(1-Rules!$C$18)-MAX(0,MIN(L14,Q14+L14-Rules!$C$19))*Rules!$C$20 -> 11039.348 | AL14: =(AJ14+AK14/2)*Inputs!$C$35 -> 13215.092 | AM14: =(AJ14+AK14/2)*Inputs!$C$42 -> 2548.6248 | AN14: =AJ14+AK14+AL14-AM14 -> 204973.17 | AO14: =AI14+AN14 -> 466406.28 | AP14: =AO14+AD14-Z14 -> 234059.81 | AQ14: =IF(AND(N14=0,O14=0,Z14>=0,AI14>=0,AN14>=0),"OK","CHECK") -> OK
A15: 9 | B15: FY35 | C15: =Inputs!$C$7+A15-1 -> 46 | D15: =Inputs!$C$13+A15-1 -> 44 | E15: =Inputs!$C$8*(1+Inputs!$C$39)^(A15-1) -> 133010.86 | F15: =Inputs!$C$14*(1+Inputs!$C$39)^(A15-1) -> 111475.77 | G15: =INDEX(Inputs!$D$49:$D$52,Inputs!$C$45)*(1+Inputs!$C$39)^(A15-1)*E15/(E15+F15) -> 0 | H15: =INDEX(Inputs!$D$49:$D$52,Inputs!$C$45)*(1+Inputs!$C$39)^(A15-1)*F15/(E15+F15) -> 0 | I15: =MIN(E15,Rules!$C$16*(1+Inputs!$C$39)^(A15-1))*Rules!$C$15 -> 15961.303 | J15: =MIN(F15,Rules!$C$16*(1+Inputs!$C$39)^(A15-1))*Rules!$C$15 -> 13377.092 | K15: =G15+I15 -> 15961.303 | L15: =H15+J15 -> 13377.092 | M15: =Rules!$C$17*(1+Inputs!$C$39)^(A15-1) -> 41170.028 | N15: =MAX(0,K15-M15) -> 0 | O15: =MAX(0,L15-M15) -> 0 | P15: =E15-G15 -> 133010.86 | Q15: =F15-H15 -> 111475.77 | R15: =SUMPRODUCT(--(P15>Rules!$B$7:$B$11),(P15-Rules!$B$7:$B$11),Rules!$E$7:$E$11)+P15*Rules!$C$14 -> 33083.475 | S15: =SUMPRODUCT(--(Q15>Rules!$B$7:$B$11),(Q15-Rules!$B$7:$B$11),Rules!$E$7:$E$11)+Q15*Rules!$C$14 -> 26192.245 | T15: =(P15-R15)+(Q15-S15) -> 185210.91 | U15: =Inputs!$C$20*(1+Inputs!$C$38)^(A15-1) -> 116966.68 | V15: =Z14 -> 588744.84 | W15: =V15*Inputs!$C$26 -> 34735.946 | X15: =IF(V15<=0,0,MIN(Inputs!$C$28,V15+W15)) -> 55789.167 | Y15: =IF(V15<=0,0,MIN(INDEX(Inputs!$E$49:$E$52,Inputs!$C$45),MAX(0,V15+W15-X15))) -> 0 | Z15: =MAX(0,V15+W15-X15-Y15) -> 567691.62 | AA15: =AD14 -> 356398.37 | AB15: =INDEX(Inputs!$F$49:$F$52,Inputs!$C$45)+IF(V15<=0,Inputs!$C$28+INDEX(Inputs!$E$49:$E$52,Inputs!$C$45),0) -> 23120 | AC15: =(AA15+AB15/2)*Inputs!$C$36 -> 23917.294 | AD15: =AA15+AB15+AC15 -> 403435.66 | AE15: =AI14 -> 261433.11 | AF15: =K15*(1-Rules!$C$18)-MAX(0,MIN(K15,P15+K15-Rules!$C$19))*Rules!$C$20 -> 13567.108 | AG15: =(AE15+AF15/2)*Inputs!$C$35 -> 18775.167 | AH15: =(AE15+AF15/2)*Inputs!$C$42 -> 3620.925 | AI15: =AE15+AF15+AG15-AH15 -> 290154.46 | AJ15: =AN14 -> 204973.17 | AK15: =L15*(1-Rules!$C$18)-MAX(0,MIN(L15,Q15+L15-Rules!$C$19))*Rules!$C$20 -> 11370.528 | AL15: =(AJ15+AK15/2)*Inputs!$C$35 -> 14746.09 | AM15: =(AJ15+AK15/2)*Inputs!$C$42 -> 2843.8888 | AN15: =AJ15+AK15+AL15-AM15 -> 228245.9 | AO15: =AI15+AN15 -> 518400.36 | AP15: =AO15+AD15-Z15 -> 354144.4 | AQ15: =IF(AND(N15=0,O15=0,Z15>=0,AI15>=0,AN15>=0),"OK","CHECK") -> OK
A16: 10 | B16: FY36 | C16: =Inputs!$C$7+A16-1 -> 47 | D16: =Inputs!$C$13+A16-1 -> 45 | E16: =Inputs!$C$8*(1+Inputs!$C$39)^(A16-1) -> 137001.18 | F16: =Inputs!$C$14*(1+Inputs!$C$39)^(A16-1) -> 114820.04 | G16: =INDEX(Inputs!$D$49:$D$52,Inputs!$C$45)*(1+Inputs!$C$39)^(A16-1)*E16/(E16+F16) -> 0 | H16: =INDEX(Inputs!$D$49:$D$52,Inputs!$C$45)*(1+Inputs!$C$39)^(A16-1)*F16/(E16+F16) -> 0 | I16: =MIN(E16,Rules!$C$16*(1+Inputs!$C$39)^(A16-1))*Rules!$C$15 -> 16440.142 | J16: =MIN(F16,Rules!$C$16*(1+Inputs!$C$39)^(A16-1))*Rules!$C$15 -> 13778.405 | K16: =G16+I16 -> 16440.142 | L16: =H16+J16 -> 13778.405 | M16: =Rules!$C$17*(1+Inputs!$C$39)^(A16-1) -> 42405.128 | N16: =MAX(0,K16-M16) -> 0 | O16: =MAX(0,L16-M16) -> 0 | P16: =E16-G16 -> 137001.18 | Q16: =F16-H16 -> 114820.04 | R16: =SUMPRODUCT(--(P16>Rules!$B$7:$B$11),(P16-Rules!$B$7:$B$11),Rules!$E$7:$E$11)+P16*Rules!$C$14 -> 34500.462 | S16: =SUMPRODUCT(--(Q16>Rules!$B$7:$B$11),(Q16-Rules!$B$7:$B$11),Rules!$E$7:$E$11)+Q16*Rules!$C$14 -> 27262.413 | T16: =(P16-R16)+(Q16-S16) -> 190058.35 | U16: =Inputs!$C$20*(1+Inputs!$C$38)^(A16-1) -> 119890.85 | V16: =Z15 -> 567691.62 | W16: =V16*Inputs!$C$26 -> 33493.806 | X16: =IF(V16<=0,0,MIN(Inputs!$C$28,V16+W16)) -> 55789.167 | Y16: =IF(V16<=0,0,MIN(INDEX(Inputs!$E$49:$E$52,Inputs!$C$45),MAX(0,V16+W16-X16))) -> 0 | Z16: =MAX(0,V16+W16-X16-Y16) -> 545396.26 | AA16: =AD15 -> 403435.66 | AB16: =INDEX(Inputs!$F$49:$F$52,Inputs!$C$45)+IF(V16<=0,Inputs!$C$28+INDEX(Inputs!$E$49:$E$52,Inputs!$C$45),0) -> 23120 | AC16: =(AA16+AB16/2)*Inputs!$C$36 -> 26974.718 | AD16: =AA16+AB16+AC16 -> 453530.38 | AE16: =AI15 -> 290154.46 | AF16: =K16*(1-Rules!$C$18)-MAX(0,MIN(K16,P16+K16-Rules!$C$19))*Rules!$C$20 -> 13974.121 | AG16: =(AE16+AF16/2)*Inputs!$C$35 -> 20799.907 | AH16: =(AE16+AF16/2)*Inputs!$C$42 -> 4011.4106 | AI16: =AE16+AF16+AG16-AH16 -> 320917.08 | AJ16: =AN15 -> 228245.9 | AK16: =L16*(1-Rules!$C$18)-MAX(0,MIN(L16,Q16+L16-Rules!$C$19))*Rules!$C$20 -> 11711.644 | AL16: =(AJ16+AK16/2)*Inputs!$C$35 -> 16387.12 | AM16: =(AJ16+AK16/2)*Inputs!$C$42 -> 3160.3732 | AN16: =AJ16+AK16+AL16-AM16 -> 253184.29 | AO16: =AI16+AN16 -> 574101.37 | AP16: =AO16+AD16-Z16 -> 482235.49 | AQ16: =IF(AND(N16=0,O16=0,Z16>=0,AI16>=0,AN16>=0),"OK","CHECK") -> OK
A17: 11 | B17: FY37 | C17: =Inputs!$C$7+A17-1 -> 48 | D17: =Inputs!$C$13+A17-1 -> 46 | E17: =Inputs!$C$8*(1+Inputs!$C$39)^(A17-1) -> 141111.22 | F17: =Inputs!$C$14*(1+Inputs!$C$39)^(A17-1) -> 118264.64 | G17: =INDEX(Inputs!$D$49:$D$52,Inputs!$C$45)*(1+Inputs!$C$39)^(A17-1)*E17/(E17+F17) -> 0 | H17: =INDEX(Inputs!$D$49:$D$52,Inputs!$C$45)*(1+Inputs!$C$39)^(A17-1)*F17/(E17+F17) -> 0 | I17: =MIN(E17,Rules!$C$16*(1+Inputs!$C$39)^(A17-1))*Rules!$C$15 -> 16933.346 | J17: =MIN(F17,Rules!$C$16*(1+Inputs!$C$39)^(A17-1))*Rules!$C$15 -> 14191.757 | K17: =G17+I17 -> 16933.346 | L17: =H17+J17 -> 14191.757 | M17: =Rules!$C$17*(1+Inputs!$C$39)^(A17-1) -> 43677.282 | N17: =MAX(0,K17-M17) -> 0 | O17: =MAX(0,L17-M17) -> 0 | P17: =E17-G17 -> 141111.22 | Q17: =F17-H17 -> 118264.64 | R17: =SUMPRODUCT(--(P17>Rules!$B$7:$B$11),(P17-Rules!$B$7:$B$11),Rules!$E$7:$E$11)+P17*Rules!$C$14 -> 36103.376 | S17: =SUMPRODUCT(--(Q17>Rules!$B$7:$B$11),(Q17-Rules!$B$7:$B$11),Rules!$E$7:$E$11)+Q17*Rules!$C$14 -> 28364.685 | T17: =(P17-R17)+(Q17-S17) -> 194907.8 | U17: =Inputs!$C$20*(1+Inputs!$C$38)^(A17-1) -> 122888.12 | V17: =Z16 -> 545396.26 | W17: =V17*Inputs!$C$26 -> 32178.379 | X17: =IF(V17<=0,0,MIN(Inputs!$C$28,V17+W17)) -> 55789.167 | Y17: =IF(V17<=0,0,MIN(INDEX(Inputs!$E$49:$E$52,Inputs!$C$45),MAX(0,V17+W17-X17))) -> 0 | Z17: =MAX(0,V17+W17-X17-Y17) -> 521785.47 | AA17: =AD16 -> 453530.38 | AB17: =INDEX(Inputs!$F$49:$F$52,Inputs!$C$45)+IF(V17<=0,Inputs!$C$28+INDEX(Inputs!$E$49:$E$52,Inputs!$C$45),0) -> 23120 | AC17: =(AA17+AB17/2)*Inputs!$C$36 -> 30230.875 | AD17: =AA17+AB17+AC17 -> 506881.26 | AE17: =AI16 -> 320917.08 | AF17: =K17*(1-Rules!$C$18)-MAX(0,MIN(K17,P17+K17-Rules!$C$19))*Rules!$C$20 -> 14393.344 | AG17: =(AE17+AF17/2)*Inputs!$C$35 -> 22967.963 | AH17: =(AE17+AF17/2)*Inputs!$C$42 -> 4429.5357 | AI17: =AE17+AF17+AG17-AH17 -> 353848.85 | AJ17: =AN16 -> 253184.29 | AK17: =L17*(1-Rules!$C$18)-MAX(0,MIN(L17,Q17+L17-Rules!$C$19))*Rules!$C$20 -> 12062.993 | AL17: =(AJ17+AK17/2)*Inputs!$C$35 -> 18145.105 | AM17: =(AJ17+AK17/2)*Inputs!$C$42 -> 3499.4131 | AN17: =AJ17+AK17+AL17-AM17 -> 279892.97 | AO17: =AI17+AN17 -> 633741.82 | AP17: =AO17+AD17-Z17 -> 618837.61 | AQ17: =IF(AND(N17=0,O17=0,Z17>=0,AI17>=0,AN17>=0),"OK","CHECK") -> OK
A18: 12 | B18: FY38 | C18: =Inputs!$C$7+A18-1 -> 49 | D18: =Inputs!$C$13+A18-1 -> 47 | E18: =Inputs!$C$8*(1+Inputs!$C$39)^(A18-1) -> 145344.56 | F18: =Inputs!$C$14*(1+Inputs!$C$39)^(A18-1) -> 121812.58 | G18: =INDEX(Inputs!$D$49:$D$52,Inputs!$C$45)*(1+Inputs!$C$39)^(A18-1)*E18/(E18+F18) -> 0 | H18: =INDEX(Inputs!$D$49:$D$52,Inputs!$C$45)*(1+Inputs!$C$39)^(A18-1)*F18/(E18+F18) -> 0 | I18: =MIN(E18,Rules!$C$16*(1+Inputs!$C$39)^(A18-1))*Rules!$C$15 -> 17441.347 | J18: =MIN(F18,Rules!$C$16*(1+Inputs!$C$39)^(A18-1))*Rules!$C$15 -> 14617.51 | K18: =G18+I18 -> 17441.347 | L18: =H18+J18 -> 14617.51 | M18: =Rules!$C$17*(1+Inputs!$C$39)^(A18-1) -> 44987.601 | N18: =MAX(0,K18-M18) -> 0 | O18: =MAX(0,L18-M18) -> 0 | P18: =E18-G18 -> 145344.56 | Q18: =F18-H18 -> 121812.58 | R18: =SUMPRODUCT(--(P18>Rules!$B$7:$B$11),(P18-Rules!$B$7:$B$11),Rules!$E$7:$E$11)+P18*Rules!$C$14 -> 37754.377 | S18: =SUMPRODUCT(--(Q18>Rules!$B$7:$B$11),(Q18-Rules!$B$7:$B$11),Rules!$E$7:$E$11)+Q18*Rules!$C$14 -> 29500.026 | T18: =(P18-R18)+(Q18-S18) -> 199902.73 | U18: =Inputs!$C$20*(1+Inputs!$C$38)^(A18-1) -> 125960.32 | V18: =Z17 -> 521785.47 | W18: =V18*Inputs!$C$26 -> 30785.343 | X18: =IF(V18<=0,0,MIN(Inputs!$C$28,V18+W18)) -> 55789.167 | Y18: =IF(V18<=0,0,MIN(INDEX(Inputs!$E$49:$E$52,Inputs!$C$45),MAX(0,V18+W18-X18))) -> 0 | Z18: =MAX(0,V18+W18-X18-Y18) -> 496781.65 | AA18: =AD17 -> 506881.26 | AB18: =INDEX(Inputs!$F$49:$F$52,Inputs!$C$45)+IF(V18<=0,Inputs!$C$28+INDEX(Inputs!$E$49:$E$52,Inputs!$C$45),0) -> 23120 | AC18: =(AA18+AB18/2)*Inputs!$C$36 -> 33698.682 | AD18: =AA18+AB18+AC18 -> 563699.94 | AE18: =AI17 -> 353848.85 | AF18: =K18*(1-Rules!$C$18)-MAX(0,MIN(K18,P18+K18-Rules!$C$19))*Rules!$C$20 -> 14825.145 | AG18: =(AE18+AF18/2)*Inputs!$C$35 -> 25288.3 | AH18: =(AE18+AF18/2)*Inputs!$C$42 -> 4877.0292 | AI18: =AE18+AF18+AG18-AH18 -> 389085.27 | AJ18: =AN17 -> 279892.97 | AK18: =L18*(1-Rules!$C$18)-MAX(0,MIN(L18,Q18+L18-Rules!$C$19))*Rules!$C$20 -> 12424.883 | AL18: =(AJ18+AK18/2)*Inputs!$C$35 -> 20027.379 | AM18: =(AJ18+AK18/2)*Inputs!$C$42 -> 3862.4231 | AN18: =AJ18+AK18+AL18-AM18 -> 308482.81 | AO18: =AI18+AN18 -> 697568.08 | AP18: =AO18+AD18-Z18 -> 764486.37 | AQ18: =IF(AND(N18=0,O18=0,Z18>=0,AI18>=0,AN18>=0),"OK","CHECK") -> OK
A19: 13 | B19: FY39 | C19: =Inputs!$C$7+A19-1 -> 50 | D19: =Inputs!$C$13+A19-1 -> 48 | E19: =Inputs!$C$8*(1+Inputs!$C$39)^(A19-1) -> 149704.89 | F19: =Inputs!$C$14*(1+Inputs!$C$39)^(A19-1) -> 125466.96 | G19: =INDEX(Inputs!$D$49:$D$52,Inputs!$C$45)*(1+Inputs!$C$39)^(A19-1)*E19/(E19+F19) -> 0 | H19: =INDEX(Inputs!$D$49:$D$52,Inputs!$C$45)*(1+Inputs!$C$39)^(A19-1)*F19/(E19+F19) -> 0 | I19: =MIN(E19,Rules!$C$16*(1+Inputs!$C$39)^(A19-1))*Rules!$C$15 -> 17964.587 | J19: =MIN(F19,Rules!$C$16*(1+Inputs!$C$39)^(A19-1))*Rules!$C$15 -> 15056.035 | K19: =G19+I19 -> 17964.587 | L19: =H19+J19 -> 15056.035 | M19: =Rules!$C$17*(1+Inputs!$C$39)^(A19-1) -> 46337.229 | N19: =MAX(0,K19-M19) -> 0 | O19: =MAX(0,L19-M19) -> 0 | P19: =E19-G19 -> 149704.89 | Q19: =F19-H19 -> 125466.96 | R19: =SUMPRODUCT(--(P19>Rules!$B$7:$B$11),(P19-Rules!$B$7:$B$11),Rules!$E$7:$E$11)+P19*Rules!$C$14 -> 39454.908 | S19: =SUMPRODUCT(--(Q19>Rules!$B$7:$B$11),(Q19-Rules!$B$7:$B$11),Rules!$E$7:$E$11)+Q19*Rules!$C$14 -> 30669.427 | T19: =(P19-R19)+(Q19-S19) -> 205047.52 | U19: =Inputs!$C$20*(1+Inputs!$C$38)^(A19-1) -> 129109.33 | V19: =Z18 -> 496781.65 | W19: =V19*Inputs!$C$26 -> 29310.117 | X19: =IF(V19<=0,0,MIN(Inputs!$C$28,V19+W19)) -> 55789.167 | Y19: =IF(V19<=0,0,MIN(INDEX(Inputs!$E$49:$E$52,Inputs!$C$45),MAX(0,V19+W19-X19))) -> 0 | Z19: =MAX(0,V19+W19-X19-Y19) -> 470302.6 | AA19: =AD18 -> 563699.94 | AB19: =INDEX(Inputs!$F$49:$F$52,Inputs!$C$45)+IF(V19<=0,Inputs!$C$28+INDEX(Inputs!$E$49:$E$52,Inputs!$C$45),0) -> 23120 | AC19: =(AA19+AB19/2)*Inputs!$C$36 -> 37391.896 | AD19: =AA19+AB19+AC19 -> 624211.83 | AE19: =AI18 -> 389085.27 | AF19: =K19*(1-Rules!$C$18)-MAX(0,MIN(K19,P19+K19-Rules!$C$19))*Rules!$C$20 -> 15269.899 | AG19: =(AE19+AF19/2)*Inputs!$C$35 -> 27770.415 | AH19: =(AE19+AF19/2)*Inputs!$C$42 -> 5355.7229 | AI19: =AE19+AF19+AG19-AH19 -> 426769.86 | AJ19: =AN18 -> 308482.81 | AK19: =L19*(1-Rules!$C$18)-MAX(0,MIN(L19,Q19+L19-Rules!$C$19))*Rules!$C$20 -> 12797.63 | AL19: =(AJ19+AK19/2)*Inputs!$C$35 -> 22041.714 | AM19: =(AJ19+AK19/2)*Inputs!$C$42 -> 4250.9019 | AN19: =AJ19+AK19+AL19-AM19 -> 339071.25 | AO19: =AI19+AN19 -> 765841.11 | AP19: =AO19+AD19-Z19 -> 919750.35 | AQ19: =IF(AND(N19=0,O19=0,Z19>=0,AI19>=0,AN19>=0),"OK","CHECK") -> OK
... A36: 30 | B36: FY56 | C36: =Inputs!$C$7+A36-1 -> 67 | D36: =Inputs!$C$13+A36-1 -> 65 | E36: =Inputs!$C$8*(1+Inputs!$C$39)^(A36-1) -> 247439.38 | F36: =Inputs!$C$14*(1+Inputs!$C$39)^(A36-1) -> 207377.76 | G36: =INDEX(Inputs!$D$49:$D$52,Inputs!$C$45)*(1+Inputs!$C$39)^(A36-1)*E36/(E36+F36) -> 0 | H36: =INDEX(Inputs!$D$49:$D$52,Inputs!$C$45)*(1+Inputs!$C$39)^(A36-1)*F36/(E36+F36) -> 0 | I36: =MIN(E36,Rules!$C$16*(1+Inputs!$C$39)^(A36-1))*Rules!$C$15 -> 29692.725 | J36: =MIN(F36,Rules!$C$16*(1+Inputs!$C$39)^(A36-1))*Rules!$C$15 -> 24885.332 | K36: =G36+I36 -> 29692.725 | L36: =H36+J36 -> 24885.332 | M36: =Rules!$C$17*(1+Inputs!$C$39)^(A36-1) -> 76588.379 | N36: =MAX(0,K36-M36) -> 0 | O36: =MAX(0,L36-M36) -> 0 | P36: =E36-G36 -> 247439.38 | Q36: =F36-H36 -> 207377.76 | R36: =SUMPRODUCT(--(P36>Rules!$B$7:$B$11),(P36-Rules!$B$7:$B$11),Rules!$E$7:$E$11)+P36*Rules!$C$14 -> 82166.508 | S36: =SUMPRODUCT(--(Q36>Rules!$B$7:$B$11),(Q36-Rules!$B$7:$B$11),Rules!$E$7:$E$11)+Q36*Rules!$C$14 -> 63337.549 | T36: =(P36-R36)+(Q36-S36) -> 309313.09 | U36: =Inputs!$C$20*(1+Inputs!$C$38)^(A36-1) -> 196455.11 | V36: =Z35 -> 0 | W36: =V36*Inputs!$C$26 -> 0 | X36: =IF(V36<=0,0,MIN(Inputs!$C$28,V36+W36)) -> 0 | Y36: =IF(V36<=0,0,MIN(INDEX(Inputs!$E$49:$E$52,Inputs!$C$45),MAX(0,V36+W36-X36))) -> 0 | Z36: =MAX(0,V36+W36-X36-Y36) -> 0 | AA36: =AD35 -> 2532661.3 | AB36: =INDEX(Inputs!$F$49:$F$52,Inputs!$C$45)+IF(V36<=0,Inputs!$C$28+INDEX(Inputs!$E$49:$E$52,Inputs!$C$45),0) -> 78909.167 | AC36: =(AA36+AB36/2)*Inputs!$C$36 -> 167187.53 | AD36: =AA36+AB36+AC36 -> 2778758 | AE36: =AI35 -> 1513971.2 | AF36: =K36*(1-Rules!$C$18)-MAX(0,MIN(K36,P36+K36-Rules!$C$19))*Rules!$C$20 -> 21169.001 | AG36: =(AE36+AF36/2)*Inputs!$C$35 -> 106718.9 | AH36: =(AE36+AF36/2)*Inputs!$C$42 -> 20581.502 | AI36: =AE36+AF36+AG36-AH36 -> 1621277.6 | AJ36: =AN35 -> 1228549.1 | AK36: =L36*(1-Rules!$C$18)-MAX(0,MIN(L36,Q36+L36-Rules!$C$19))*Rules!$C$20 -> 21152.532 | AL36: =(AJ36+AK36/2)*Inputs!$C$35 -> 86738.773 | AM36: =(AJ36+AK36/2)*Inputs!$C$42 -> 16728.192 | AN36: =AJ36+AK36+AL36-AM36 -> 1319712.2 | AO36: =AI36+AN36 -> 2940989.8 | AP36: =AO36+AD36-Z36 -> 5719747.8 | AQ36: =IF(AND(N36=0,O36=0,Z36>=0,AI36>=0,AN36>=0),"OK","CHECK") -> OK

Sheet Scenarios
A2: SCENARIOS - all four strategies run side by side
A3: Simplified roll-forward. The Engine sheet holds the detailed version of whichever scenario is active.
A5: SUMMARY AT RETIREMENT | C5: 1. Base case | H5: 2. Salary sacrifice | M5: 3. Extra mortgage | R5: 4. Split 50/50
A6: Terminal super - nominal ($) | C6: =C53 -> 2892661 | H6: =H53 -> 5917581.3 | M6: =M53 -> 2892661 | R6: =R53 -> 4405121.2
A7: Terminal super - today's dollars ($) | C7: =C53/(1+Inputs!$C$38)^Inputs!$C$19 -> 1413531.4 | H7: =H53/(1+Inputs!$C$38)^Inputs!$C$19 -> 2891692.7 | M7: =M53/(1+Inputs!$C$38)^Inputs!$C$19 -> 1413531.4 | R7: =R53/(1+Inputs!$C$38)^Inputs!$C$19 -> 2152612
A8: Terminal outside super - today's dollars ($) | C8: =E53/(1+Inputs!$C$38)^Inputs!$C$19 -> 1357323.1 | H8: =J53/(1+Inputs!$C$38)^Inputs!$C$19 -> 381472.98 | M8: =O53/(1+Inputs!$C$38)^Inputs!$C$19 -> 1257883.6 | R8: =T53/(1+Inputs!$C$38)^Inputs!$C$19 -> 797939.15
A9: Mortgage remaining ($) | C9: =D53 -> 0 | H9: =I53 -> 0 | M9: =N53 -> 0 | R9: =S53 -> 0
A10: Net wealth - today's dollars ($) | C10: =F53/(1+Inputs!$C$38)^Inputs!$C$19 -> 2770854.4 | H10: =K53/(1+Inputs!$C$38)^Inputs!$C$19 -> 3273165.7 | M10: =P53/(1+Inputs!$C$38)^Inputs!$C$19 -> 2671415 | R10: =U53/(1+Inputs!$C$38)^Inputs!$C$19 -> 2950551.2
A11: Years until mortgage cleared | C11: =COUNTIF(D24:D53,">0") -> 24 | H11: =COUNTIF(I24:I53,">0") -> 24 | M11: =COUNTIF(N24:N53,">0") -> 13 | R11: =COUNTIF(S24:S53,">0") -> 17
A12: Super vs ASFA lump sum ($730,000, today's $) | C12: =C53/(1+Inputs!$C$38)^Inputs!$C$19-Rules!$C$26 -> 683531.37 | H12: =H53/(1+Inputs!$C$38)^Inputs!$C$19-Rules!$C$26 -> 2161692.7 | M12: =M53/(1+Inputs!$C$38)^Inputs!$C$19-Rules!$C$26 -> 683531.37 | R12: =R53/(1+Inputs!$C$38)^Inputs!$C$19-Rules!$C$26 -> 1422612
A13: Meets ASFA comfortable benchmark | C13: =IF(C53/(1+Inputs!$C$38)^Inputs!$C$19>=Rules!$C$26,"Yes","No") -> Yes | H13: =IF(H53/(1+Inputs!$C$38)^Inputs!$C$19>=Rules!$C$26,"Yes","No") -> Yes | M13: =IF(M53/(1+Inputs!$C$38)^Inputs!$C$19>=Rules!$C$26,"Yes","No") -> Yes | R13: =IF(R53/(1+Inputs!$C$38)^Inputs!$C$19>=Rules!$C$26,"Yes","No") -> Yes
A14: Retirement income at 4% drawdown (today's $) | C14: =(C53+E53)/(1+Inputs!$C$38)^Inputs!$C$19*Rules!$C$29 -> 110834.18 | H14: =(H53+J53)/(1+Inputs!$C$38)^Inputs!$C$19*Rules!$C$29 -> 130926.63 | M14: =(M53+O53)/(1+Inputs!$C$38)^Inputs!$C$19*Rules!$C$29 -> 106856.6 | R14: =(R53+T53)/(1+Inputs!$C$38)^Inputs!$C$19*Rules!$C$29 -> 118022.05
A15: 70% replacement target (today's $) | C15: =(Inputs!$C$8+Inputs!$C$14)*Rules!$C$28 -> 135100 | H15: =(Inputs!$C$8+Inputs!$C$14)*Rules!$C$28 -> 135100 | M15: =(Inputs!$C$8+Inputs!$C$14)*Rules!$C$28 -> 135100 | R15: =(Inputs!$C$8+Inputs!$C$14)*Rules!$C$28 -> 135100
A16: Surplus / (shortfall) vs target ($) | C16: =(C53+E53)/(1+Inputs!$C$38)^Inputs!$C$19*Rules!$C$29-(Inputs!$C$8+Inputs!$C$14)*Rules!$C$28 -> -24265.822 | H16: =(H53+J53)/(1+Inputs!$C$38)^Inputs!$C$19*Rules!$C$29-(Inputs!$C$8+Inputs!$C$14)*Rules!$C$28 -> -4173.3729 | M16: =(M53+O53)/(1+Inputs!$C$38)^Inputs!$C$19*Rules!$C$29-(Inputs!$C$8+Inputs!$C$14)*Rules!$C$28 -> -28243.401 | R16: =(R53+T53)/(1+Inputs!$C$38)^Inputs!$C$19*Rules!$C$29-(Inputs!$C$8+Inputs!$C$14)*Rules!$C$28 -> -17077.953
C22: 1. Base case | H22: 2. Salary sacrifice | M22: 3. Extra mortgage | R22: 4. Split 50/50
A23: Year | B23: Financial year | C23: Super ($) | D23: Mortgage ($) | E23: Outside ($) | F23: Net wealth ($) | H23: Super ($) | I23: Mortgage ($) | J23: Outside ($) | K23: Net wealth ($) | M23: Super ($) | N23: Mortgage ($) | O23: Outside ($) | P23: Net wealth ($) | R23: Super ($) | S23: Mortgage ($) | T23: Outside ($) | U23: Net wealth ($)
A24: 1 | B24: FY27 | C24: =(Inputs!$C$9+Inputs!$C$15)*(1+Inputs!$C$35-Inputs!$C$42)+((Engine!E7+Engine!F7)*Rules!$C$15+Inputs!$D$49*(1+Inputs!$C$39)^(A24-1))*(1-Rules!$C$18) -> 188726 | D24: =MAX(0,Inputs!$C$25*(1+Inputs!$C$26)-Inputs!$C$28-Inputs!$E$49) -> 706690.83 | E24: =(Inputs!$C$31+Inputs!$C$32)*(1+Inputs!$C$36)+Inputs!$F$49 -> 97670 | F24: =C24+E24-D24 -> -420294.83 | H24: =(Inputs!$C$9+Inputs!$C$15)*(1+Inputs!$C$35-Inputs!$C$42)+((Engine!E7+Engine!F7)*Rules!$C$15+Inputs!$D$50*(1+Inputs!$C$39)^(A24-1))*(1-Rules!$C$18) -> 217626 | I24: =MAX(0,Inputs!$C$25*(1+Inputs!$C$26)-Inputs!$C$28-Inputs!$E$50) -> 706690.83 | J24: =(Inputs!$C$31+Inputs!$C$32)*(1+Inputs!$C$36)+Inputs!$F$50 -> 74550 | K24: =H24+J24-I24 -> -414514.83 | M24: =(Inputs!$C$9+Inputs!$C$15)*(1+Inputs!$C$35-Inputs!$C$42)+((Engine!E7+Engine!F7)*Rules!$C$15+Inputs!$D$51*(1+Inputs!$C$39)^(A24-1))*(1-Rules!$C$18) -> 188726 | N24: =MAX(0,Inputs!$C$25*(1+Inputs!$C$26)-Inputs!$C$28-Inputs!$E$51) -> 683570.83 | O24: =(Inputs!$C$31+Inputs!$C$32)*(1+Inputs!$C$36)+Inputs!$F$51 -> 74550 | P24: =M24+O24-N24 -> -420294.83 | R24: =(Inputs!$C$9+Inputs!$C$15)*(1+Inputs!$C$35-Inputs!$C$42)+((Engine!E7+Engine!F7)*Rules!$C$15+Inputs!$D$52*(1+Inputs!$C$39)^(A24-1))*(1-Rules!$C$18) -> 203176 | S24: =MAX(0,Inputs!$C$25*(1+Inputs!$C$26)-Inputs!$C$28-Inputs!$E$52) -> 695130.83 | T24: =(Inputs!$C$31+Inputs!$C$32)*(1+Inputs!$C$36)+Inputs!$F$52 -> 74550 | U24: =R24+T24-S24 -> -417404.83
A25: 2 | B25: FY28 | C25: =C24*(1+Inputs!$C$35-Inputs!$C$42)+((Engine!E8+Engine!F8)*Rules!$C$15+Inputs!$D$49*(1+Inputs!$C$39)^(A25-1))*(1-Rules!$C$18) -> 219665.6 | D25: =IF(D24<=0,0,MAX(0,D24*(1+Inputs!$C$26)-Inputs!$C$28-Inputs!$E$49)) -> 692596.43 | E25: =E24*(1+Inputs!$C$36)+Inputs!$F$49+IF(D24<=0,Inputs!$C$28+Inputs!$E$49,0) -> 127138.55 | F25: =C25+E25-D25 -> -345792.28 | H25: =H24*(1+Inputs!$C$35-Inputs!$C$42)+((Engine!E8+Engine!F8)*Rules!$C$15+Inputs!$D$50*(1+Inputs!$C$39)^(A25-1))*(1-Rules!$C$18) -> 279965.45 | I25: =IF(I24<=0,0,MAX(0,I24*(1+Inputs!$C$26)-Inputs!$C$28-Inputs!$E$50)) -> 692596.43 | J25: =J24*(1+Inputs!$C$36)+Inputs!$F$50+IF(I24<=0,Inputs!$C$28+Inputs!$E$50,0) -> 79395.75 | K25: =H25+J25-I25 -> -333235.23 | M25: =M24*(1+Inputs!$C$35-Inputs!$C$42)+((Engine!E8+Engine!F8)*Rules!$C$15+Inputs!$D$51*(1+Inputs!$C$39)^(A25-1))*(1-Rules!$C$18) -> 219665.6 | N25: =IF(N24<=0,0,MAX(0,N24*(1+Inputs!$C$26)-Inputs!$C$28-Inputs!$E$51)) -> 644992.35 | O25: =O24*(1+Inputs!$C$36)+Inputs!$F$51+IF(N24<=0,Inputs!$C$28+Inputs!$E$51,0) -> 79395.75 | P25: =M25+O25-N25 -> -345931 | R25: =R24*(1+Inputs!$C$35-Inputs!$C$42)+((Engine!E8+Engine!F8)*Rules!$C$15+Inputs!$D$52*(1+Inputs!$C$39)^(A25-1))*(1-Rules!$C$18) -> 249815.52 | S25: =IF(S24<=0,0,MAX(0,S24*(1+Inputs!$C$26)-Inputs!$C$28-Inputs!$E$52)) -> 668794.39 | T25: =T24*(1+Inputs!$C$36)+Inputs!$F$52+IF(S24<=0,Inputs!$C$28+Inputs!$E$52,0) -> 79395.75 | U25: =R25+T25-S25 -> -339583.11
A26: 3 | B26: FY29 | C26: =C25*(1+Inputs!$C$35-Inputs!$C$42)+((Engine!E9+Engine!F9)*Rules!$C$15+Inputs!$D$49*(1+Inputs!$C$39)^(A26-1))*(1-Rules!$C$18) -> 252961.58 | D26: =IF(D25<=0,0,MAX(0,D25*(1+Inputs!$C$26)-Inputs!$C$28-Inputs!$E$49)) -> 677670.45 | E26: =E25*(1+Inputs!$C$36)+Inputs!$F$49+IF(D25<=0,Inputs!$C$28+Inputs!$E$49,0) -> 158522.56 | F26: =C26+E26-D26 -> -266186.31 | H26: =H25*(1+Inputs!$C$35-Inputs!$C$42)+((Engine!E9+Engine!F9)*Rules!$C$15+Inputs!$D$50*(1+Inputs!$C$39)^(A26-1))*(1-Rules!$C$18) -> 347328.38 | I26: =IF(I25<=0,0,MAX(0,I25*(1+Inputs!$C$26)-Inputs!$C$28-Inputs!$E$50)) -> 677670.45 | J26: =J25*(1+Inputs!$C$36)+Inputs!$F$50+IF(I25<=0,Inputs!$C$28+Inputs!$E$50,0) -> 84556.474 | K26: =H26+J26-I26 -> -245785.59 | M26: =M25*(1+Inputs!$C$35-Inputs!$C$42)+((Engine!E9+Engine!F9)*Rules!$C$15+Inputs!$D$51*(1+Inputs!$C$39)^(A26-1))*(1-Rules!$C$18) -> 252961.58 | N26: =IF(N25<=0,0,MAX(0,N25*(1+Inputs!$C$26)-Inputs!$C$28-Inputs!$E$51)) -> 604137.73 | O26: =O25*(1+Inputs!$C$36)+Inputs!$F$51+IF(N25<=0,Inputs!$C$28+Inputs!$E$51,0) -> 84556.474 | P26: =M26+O26-N26 -> -266619.67 | R26: =R25*(1+Inputs!$C$35-Inputs!$C$42)+((Engine!E9+Engine!F9)*Rules!$C$15+Inputs!$D$52*(1+Inputs!$C$39)^(A26-1))*(1-Rules!$C$18) -> 300144.98 | S26: =IF(S25<=0,0,MAX(0,S25*(1+Inputs!$C$26)-Inputs!$C$28-Inputs!$E$52)) -> 640904.09 | T26: =T25*(1+Inputs!$C$36)+Inputs!$F$52+IF(S25<=0,Inputs!$C$28+Inputs!$E$52,0) -> 84556.474 | U26: =R26+T26-S26 -> -256202.63
A27: 4 | B27: FY30 | C27: =C26*(1+Inputs!$C$35-Inputs!$C$42)+((Engine!E10+Engine!F10)*Rules!$C$15+Inputs!$D$49*(1+Inputs!$C$39)^(A27-1))*(1-Rules!$C$18) -> 288765.34 | D27: =IF(D26<=0,0,MAX(0,D26*(1+Inputs!$C$26)-Inputs!$C$28-Inputs!$E$49)) -> 661863.84 | E27: =E26*(1+Inputs!$C$36)+Inputs!$F$49+IF(D26<=0,Inputs!$C$28+Inputs!$E$49,0) -> 191946.52 | F27: =C27+E27-D27 -> -181151.98 | H27: =H26*(1+Inputs!$C$35-Inputs!$C$42)+((Engine!E10+Engine!F10)*Rules!$C$15+Inputs!$D$50*(1+Inputs!$C$39)^(A27-1))*(1-Rules!$C$18) -> 420043.67 | I27: =IF(I26<=0,0,MAX(0,I26*(1+Inputs!$C$26)-Inputs!$C$28-Inputs!$E$50)) -> 661863.84 | J27: =J26*(1+Inputs!$C$36)+Inputs!$F$50+IF(I26<=0,Inputs!$C$28+Inputs!$E$50,0) -> 90052.645 | K27: =H27+J27-I27 -> -151767.52 | M27: =M26*(1+Inputs!$C$35-Inputs!$C$42)+((Engine!E10+Engine!F10)*Rules!$C$15+Inputs!$D$51*(1+Inputs!$C$39)^(A27-1))*(1-Rules!$C$18) -> 288765.34 | N27: =IF(N26<=0,0,MAX(0,N26*(1+Inputs!$C$26)-Inputs!$C$28-Inputs!$E$51)) -> 560872.69 | O27: =O26*(1+Inputs!$C$36)+Inputs!$F$51+IF(N26<=0,Inputs!$C$28+Inputs!$E$51,0) -> 90052.645 | P27: =M27+O27-N27 -> -182054.7 | R27: =R26*(1+Inputs!$C$35-Inputs!$C$42)+((Engine!E10+Engine!F10)*Rules!$C$15+Inputs!$D$52*(1+Inputs!$C$39)^(A27-1))*(1-Rules!$C$18) -> 354404.5 | S27: =IF(S26<=0,0,MAX(0,S26*(1+Inputs!$C$26)-Inputs!$C$28-Inputs!$E$52)) -> 611368.26 | T27: =T26*(1+Inputs!$C$36)+Inputs!$F$52+IF(S26<=0,Inputs!$C$28+Inputs!$E$52,0) -> 90052.645 | U27: =R27+T27-S27 -> -166911.11
A28: 5 | B28: FY31 | C28: =C27*(1+Inputs!$C$35-Inputs!$C$42)+((Engine!E11+Engine!F11)*Rules!$C$15+Inputs!$D$49*(1+Inputs!$C$39)^(A28-1))*(1-Rules!$C$18) -> 327237.34 | D28: =IF(D27<=0,0,MAX(0,D27*(1+Inputs!$C$26)-Inputs!$C$28-Inputs!$E$49)) -> 645124.64 | E28: =E27*(1+Inputs!$C$36)+Inputs!$F$49+IF(D27<=0,Inputs!$C$28+Inputs!$E$49,0) -> 227543.05 | F28: =C28+E28-D28 -> -90344.246 | H28: =H27*(1+Inputs!$C$35-Inputs!$C$42)+((Engine!E11+Engine!F11)*Rules!$C$15+Inputs!$D$50*(1+Inputs!$C$39)^(A28-1))*(1-Rules!$C$18) -> 498460.11 | I28: =IF(I27<=0,0,MAX(0,I27*(1+Inputs!$C$26)-Inputs!$C$28-Inputs!$E$50)) -> 645124.64 | J28: =J27*(1+Inputs!$C$36)+Inputs!$F$50+IF(I27<=0,Inputs!$C$28+Inputs!$E$50,0) -> 95906.066 | K28: =H28+J28-I28 -> -50758.459 | M28: =M27*(1+Inputs!$C$35-Inputs!$C$42)+((Engine!E11+Engine!F11)*Rules!$C$15+Inputs!$D$51*(1+Inputs!$C$39)^(A28-1))*(1-Rules!$C$18) -> 327237.34 | N28: =IF(N27<=0,0,MAX(0,N27*(1+Inputs!$C$26)-Inputs!$C$28-Inputs!$E$51)) -> 515055.01 | O28: =O27*(1+Inputs!$C$36)+Inputs!$F$51+IF(N27<=0,Inputs!$C$28+Inputs!$E$51,0) -> 95906.066 | P28: =M28+O28-N28 -> -91911.597 | R28: =R27*(1+Inputs!$C$35-Inputs!$C$42)+((Engine!E11+Engine!F11)*Rules!$C$15+Inputs!$D$52*(1+Inputs!$C$39)^(A28-1))*(1-Rules!$C$18) -> 412848.73 | S28: =IF(S27<=0,0,MAX(0,S27*(1+Inputs!$C$26)-Inputs!$C$28-Inputs!$E$52)) -> 580089.82 | T28: =T27*(1+Inputs!$C$36)+Inputs!$F$52+IF(S27<=0,Inputs!$C$28+Inputs!$E$52,0) -> 95906.066 | U28: =R28+T28-S28 -> -71335.028
A29: 6 | B29: FY32 | C29: =C28*(1+Inputs!$C$35-Inputs!$C$42)+((Engine!E12+Engine!F12)*Rules!$C$15+Inputs!$D$49*(1+Inputs!$C$39)^(A29-1))*(1-Rules!$C$18) -> 368547.72 | D29: =IF(D28<=0,0,MAX(0,D28*(1+Inputs!$C$26)-Inputs!$C$28-Inputs!$E$49)) -> 627397.82 | E29: =E28*(1+Inputs!$C$36)+Inputs!$F$49+IF(D28<=0,Inputs!$C$28+Inputs!$E$49,0) -> 265453.34 | F29: =C29+E29-D29 -> 6603.2443 | H29: =H28*(1+Inputs!$C$35-Inputs!$C$42)+((Engine!E12+Engine!F12)*Rules!$C$15+Inputs!$D$50*(1+Inputs!$C$39)^(A29-1))*(1-Rules!$C$18) -> 582947.6 | I29: =IF(I28<=0,0,MAX(0,I28*(1+Inputs!$C$26)-Inputs!$C$28-Inputs!$E$50)) -> 627397.82 | J29: =J28*(1+Inputs!$C$36)+Inputs!$F$50+IF(I28<=0,Inputs!$C$28+Inputs!$E$50,0) -> 102139.96 | K29: =H29+J29-I29 -> 57689.735 | M29: =M28*(1+Inputs!$C$35-Inputs!$C$42)+((Engine!E12+Engine!F12)*Rules!$C$15+Inputs!$D$51*(1+Inputs!$C$39)^(A29-1))*(1-Rules!$C$18) -> 368547.72 | N29: =IF(N28<=0,0,MAX(0,N28*(1+Inputs!$C$26)-Inputs!$C$28-Inputs!$E$51)) -> 466534.09 | O29: =O28*(1+Inputs!$C$36)+Inputs!$F$51+IF(N28<=0,Inputs!$C$28+Inputs!$E$51,0) -> 102139.96 | P29: =M29+O29-N29 -> 4153.5986 | R29: =R28*(1+Inputs!$C$35-Inputs!$C$42)+((Engine!E12+Engine!F12)*Rules!$C$15+Inputs!$D$52*(1+Inputs!$C$39)^(A29-1))*(1-Rules!$C$18) -> 475747.66 | S29: =IF(S28<=0,0,MAX(0,S28*(1+Inputs!$C$26)-Inputs!$C$28-Inputs!$E$52)) -> 546965.95 | T29: =T28*(1+Inputs!$C$36)+Inputs!$F$52+IF(S28<=0,Inputs!$C$28+Inputs!$E$52,0) -> 102139.96 | U29: =R29+T29-S29 -> 30921.667
A30: 7 | B30: FY33 | C30: =C29*(1+Inputs!$C$35-Inputs!$C$42)+((Engine!E13+Engine!F13)*Rules!$C$15+Inputs!$D$49*(1+Inputs!$C$39)^(A30-1))*(1-Rules!$C$18) -> 412876.78 | D30: =IF(D29<=0,0,MAX(0,D29*(1+Inputs!$C$26)-Inputs!$C$28-Inputs!$E$49)) -> 608625.13 | E30: =E29*(1+Inputs!$C$36)+Inputs!$F$49+IF(D29<=0,Inputs!$C$28+Inputs!$E$49,0) -> 305827.81 | F30: =C30+E30-D30 -> 110079.47 | H30: =H29*(1+Inputs!$C$35-Inputs!$C$42)+((Engine!E13+Engine!F13)*Rules!$C$15+Inputs!$D$50*(1+Inputs!$C$39)^(A30-1))*(1-Rules!$C$18) -> 673898.36 | I30: =IF(I29<=0,0,MAX(0,I29*(1+Inputs!$C$26)-Inputs!$C$28-Inputs!$E$50)) -> 608625.13 | J30: =J29*(1+Inputs!$C$36)+Inputs!$F$50+IF(I29<=0,Inputs!$C$28+Inputs!$E$50,0) -> 108779.06 | K30: =H30+J30-I30 -> 174052.29 | M30: =M29*(1+Inputs!$C$35-Inputs!$C$42)+((Engine!E13+Engine!F13)*Rules!$C$15+Inputs!$D$51*(1+Inputs!$C$39)^(A30-1))*(1-Rules!$C$18) -> 412876.78 | N30: =IF(N29<=0,0,MAX(0,N29*(1+Inputs!$C$26)-Inputs!$C$28-Inputs!$E$51)) -> 415150.43 | O30: =O29*(1+Inputs!$C$36)+Inputs!$F$51+IF(N29<=0,Inputs!$C$28+Inputs!$E$51,0) -> 108779.06 | P30: =M30+O30-N30 -> 106505.41 | R30: =R29*(1+Inputs!$C$35-Inputs!$C$42)+((Engine!E13+Engine!F13)*Rules!$C$15+Inputs!$D$52*(1+Inputs!$C$39)^(A30-1))*(1-Rules!$C$18) -> 543387.57 | S30: =IF(S29<=0,0,MAX(0,S29*(1+Inputs!$C$26)-Inputs!$C$28-Inputs!$E$52)) -> 511887.78 | T30: =T29*(1+Inputs!$C$36)+Inputs!$F$52+IF(S29<=0,Inputs!$C$28+Inputs!$E$52,0) -> 108779.06 | U30: =R30+T30-S30 -> 140278.85
A31: 8 | B31: FY34 | C31: =C30*(1+Inputs!$C$35-Inputs!$C$42)+((Engine!E14+Engine!F14)*Rules!$C$15+Inputs!$D$49*(1+Inputs!$C$39)^(A31-1))*(1-Rules!$C$18) -> 460415.62 | D31: =IF(D30<=0,0,MAX(0,D30*(1+Inputs!$C$26)-Inputs!$C$28-Inputs!$E$49)) -> 588744.84 | E31: =E30*(1+Inputs!$C$36)+Inputs!$F$49+IF(D30<=0,Inputs!$C$28+Inputs!$E$49,0) -> 348826.62 | F31: =C31+E31-D31 -> 220497.39 | H31: =H30*(1+Inputs!$C$35-Inputs!$C$42)+((Engine!E14+Engine!F14)*Rules!$C$15+Inputs!$D$50*(1+Inputs!$C$39)^(A31-1))*(1-Rules!$C$18) -> 771728.27 | I31: =IF(I30<=0,0,MAX(0,I30*(1+Inputs!$C$26)-Inputs!$C$28-Inputs!$E$50)) -> 588744.84 | J31: =J30*(1+Inputs!$C$36)+Inputs!$F$50+IF(I30<=0,Inputs!$C$28+Inputs!$E$50,0) -> 115849.7 | K31: =H31+J31-I31 -> 298833.12 | M31: =M30*(1+Inputs!$C$35-Inputs!$C$42)+((Engine!E14+Engine!F14)*Rules!$C$15+Inputs!$D$51*(1+Inputs!$C$39)^(A31-1))*(1-Rules!$C$18) -> 460415.62 | N31: =IF(N30<=0,0,MAX(0,N30*(1+Inputs!$C$26)-Inputs!$C$28-Inputs!$E$51)) -> 360735.14 | O31: =O30*(1+Inputs!$C$36)+Inputs!$F$51+IF(N30<=0,Inputs!$C$28+Inputs!$E$51,0) -> 115849.7 | P31: =M31+O31-N31 -> 215530.18 | R31: =R30*(1+Inputs!$C$35-Inputs!$C$42)+((Engine!E14+Engine!F14)*Rules!$C$15+Inputs!$D$52*(1+Inputs!$C$39)^(A31-1))*(1-Rules!$C$18) -> 616071.94 | S31: =IF(S30<=0,0,MAX(0,S30*(1+Inputs!$C$26)-Inputs!$C$28-Inputs!$E$52)) -> 474739.99 | T31: =T30*(1+Inputs!$C$36)+Inputs!$F$52+IF(S30<=0,Inputs!$C$28+Inputs!$E$52,0) -> 115849.7 | U31: =R31+T31-S31 -> 257181.65
A32: 9 | B32: FY35 | C32: =C31*(1+Inputs!$C$35-Inputs!$C$42)+((Engine!E15+Engine!F15)*Rules!$C$15+Inputs!$D$49*(1+Inputs!$C$39)^(A32-1))*(1-Rules!$C$18) -> 511366.74 | D32: =IF(D31<=0,0,MAX(0,D31*(1+Inputs!$C$26)-Inputs!$C$28-Inputs!$E$49)) -> 567691.62 | E32: =E31*(1+Inputs!$C$36)+Inputs!$F$49+IF(D31<=0,Inputs!$C$28+Inputs!$E$49,0) -> 394620.35 | F32: =C32+E32-D32 -> 338295.46 | H32: =H31*(1+Inputs!$C$35-Inputs!$C$42)+((Engine!E15+Engine!F15)*Rules!$C$15+Inputs!$D$50*(1+Inputs!$C$39)^(A32-1))*(1-Rules!$C$18) -> 876878.21 | I32: =IF(I31<=0,0,MAX(0,I31*(1+Inputs!$C$26)-Inputs!$C$28-Inputs!$E$50)) -> 567691.62 | J32: =J31*(1+Inputs!$C$36)+Inputs!$F$50+IF(I31<=0,Inputs!$C$28+Inputs!$E$50,0) -> 123379.93 | K32: =H32+J32-I32 -> 432566.51 | M32: =M31*(1+Inputs!$C$35-Inputs!$C$42)+((Engine!E15+Engine!F15)*Rules!$C$15+Inputs!$D$51*(1+Inputs!$C$39)^(A32-1))*(1-Rules!$C$18) -> 511366.74 | N32: =IF(N31<=0,0,MAX(0,N31*(1+Inputs!$C$26)-Inputs!$C$28-Inputs!$E$51)) -> 303109.34 | O32: =O31*(1+Inputs!$C$36)+Inputs!$F$51+IF(N31<=0,Inputs!$C$28+Inputs!$E$51,0) -> 123379.93 | P32: =M32+O32-N32 -> 331637.32 | R32: =R31*(1+Inputs!$C$35-Inputs!$C$42)+((Engine!E15+Engine!F15)*Rules!$C$15+Inputs!$D$52*(1+Inputs!$C$39)^(A32-1))*(1-Rules!$C$18) -> 694122.47 | S32: =IF(S31<=0,0,MAX(0,S31*(1+Inputs!$C$26)-Inputs!$C$28-Inputs!$E$52)) -> 435400.48 | T32: =T31*(1+Inputs!$C$36)+Inputs!$F$52+IF(S31<=0,Inputs!$C$28+Inputs!$E$52,0) -> 123379.93 | U32: =R32+T32-S32 -> 382101.92
A33: 10 | B33: FY36 | C33: =C32*(1+Inputs!$C$35-Inputs!$C$42)+((Engine!E16+Engine!F16)*Rules!$C$15+Inputs!$D$49*(1+Inputs!$C$39)^(A33-1))*(1-Rules!$C$18) -> 565944.72 | D33: =IF(D32<=0,0,MAX(0,D32*(1+Inputs!$C$26)-Inputs!$C$28-Inputs!$E$49)) -> 545396.26 | E33: =E32*(1+Inputs!$C$36)+Inputs!$F$49+IF(D32<=0,Inputs!$C$28+Inputs!$E$49,0) -> 443390.67 | F33: =C33+E33-D33 -> 463939.13 | H33: =H32*(1+Inputs!$C$35-Inputs!$C$42)+((Engine!E16+Engine!F16)*Rules!$C$15+Inputs!$D$50*(1+Inputs!$C$39)^(A33-1))*(1-Rules!$C$18) -> 989815.54 | I33: =IF(I32<=0,0,MAX(0,I32*(1+Inputs!$C$26)-Inputs!$C$28-Inputs!$E$50)) -> 545396.26 | J33: =J32*(1+Inputs!$C$36)+Inputs!$F$50+IF(I32<=0,Inputs!$C$28+Inputs!$E$50,0) -> 131399.62 | K33: =H33+J33-I33 -> 575818.9 | M33: =M32*(1+Inputs!$C$35-Inputs!$C$42)+((Engine!E16+Engine!F16)*Rules!$C$15+Inputs!$D$51*(1+Inputs!$C$39)^(A33-1))*(1-Rules!$C$18) -> 565944.72 | N33: =IF(N32<=0,0,MAX(0,N32*(1+Inputs!$C$26)-Inputs!$C$28-Inputs!$E$51)) -> 242083.63 | O33: =O32*(1+Inputs!$C$36)+Inputs!$F$51+IF(N32<=0,Inputs!$C$28+Inputs!$E$51,0) -> 131399.62 | P33: =M33+O33-N33 -> 455260.72 | R33: =R32*(1+Inputs!$C$35-Inputs!$C$42)+((Engine!E16+Engine!F16)*Rules!$C$15+Inputs!$D$52*(1+Inputs!$C$39)^(A33-1))*(1-Rules!$C$18) -> 777880.13 | S33: =IF(S32<=0,0,MAX(0,S32*(1+Inputs!$C$26)-Inputs!$C$28-Inputs!$E$52)) -> 393739.94 | T33: =T32*(1+Inputs!$C$36)+Inputs!$F$52+IF(S32<=0,Inputs!$C$28+Inputs!$E$52,0) -> 131399.62 | U33: =R33+T33-S33 -> 515539.81
